<?xml version="1.0" ?>
<!-- =================================================================================== -->
<!-- |    This document was autogenerated by xacro from /home/naoki/ros/workspaces/kinetic/quix/src/doppel_description/urdf/doppel_robot.urdf.xacro | -->
<!-- |    EDITING THIS FILE BY HAND IS NOT RECOMMENDED                                 | -->
<!-- =================================================================================== -->
<robot name="doppel" xmlns:xacro="http://ros.org/wiki/xacro">
  <material name="Black">
    <color rgba="0.0 0.0 0.0 1.0"/>
  </material>
  <material name="Blue">
    <color rgba="0.0 0.0 0.8 1.0"/>
  </material>
  <material name="Green">
    <color rgba="0.0 0.8 0.0 1.0"/>
  </material>
  <material name="Grey">
    <color rgba="0.5 0.5 0.5 1.0"/>
  </material>
  <material name="LightGrey">
    <color rgba="0.7 0.7 0.7 1.0"/>
  </material>
  <material name="DarkGrey">
    <color rgba="0.3 0.3 0.3 1.0"/>
  </material>
  <material name="SlateGrey">
    <color rgba="0.44 0.5 0.56 1.0"/>
  </material>
  <material name="SteelBlue">
    <color rgba="0.27 0.51 0.71 1.0"/>
  </material>
  <material name="LightSteelBlue">
    <color rgba="0.69 0.77 0.87 1.0"/>
  </material>
  <material name="Lavender">
    <color rgba="0.9 0.9 0.98 1.0"/>
  </material>
  <material name="Red">
    <color rgba="1.0 0.0 0.0 1.0"/>
  </material>
  <material name="Orange">
    <color rgba="1.0 0.5088 0.0468 1.0"/>
  </material>
  <material name="Magenta">
    <color rgba="1.0 0.0 1.0 1.0"/>
  </material>
  <material name="White">
    <color rgba="1.0 1.0 1.0 1.0"/>
  </material>
  <material name="Yellow">
    <color rgba="0.8 0.8 0.0 1.0"/>
  </material>
  <material name="DeepSkyBlue">
    <color rgba="0.0 0.749 1.0 1.0"/>
  </material>
  <material name="LightBlueGreen">
    <color rgba="0.49411764705882355 0.984313725490196 0.7019607843137254 1.0"/>
  </material>
  <material name="LightishRed">
    <color rgba="0.996078431372549 0.1843137254901961 0.2901960784313726 1.0"/>
  </material>
  <material name="Leaf">
    <color rgba="0.44313725490196076 0.6666666666666666 0.20392156862745098 1.0"/>
  </material>
  <material name="Pale">
    <color rgba="1.0 0.9764705882352941 0.8156862745098039 1.0"/>
  </material>
  <material name="LightOrange">
    <color rgba="0.9921568627450981 0.6666666666666666 0.2823529411764706 1.0"/>
  </material>
  <material name="LightLilac">
    <color rgba="0.9294117647058824 0.7843137254901961 1.0 1.0"/>
  </material>
  <link name="world"/>
  <joint name="world_joint" type="fixed">
    <origin rpy="0 0 0" xyz="0 0 0"/>
    <parent link="world"/>
    <child link="base_link"/>
  </joint>
  <gazebo>
    <plugin filename="libgazebo_ros_control.so" name="gazebo_ros_control">
      <robotNamespace>/</robotNamespace>
    </plugin>
  </gazebo>
  <link name="base_link">
    <inertial>
      <mass value="0.2337368"/>
      <origin xyz="0 0 0"/>
      <inertia ixx="0.00036578" ixy="0.0" ixz="0.0" iyy="0.00027028" iyz="0.0" izz="0.00019041"/>
    </inertial>
    <visual>
      <origin rpy="0 0 0" xyz="0 0 0"/>
      <geometry>
        <mesh filename="package://doppel_description/meshes/base.dae" scale="1 1 1"/>
      </geometry>
      <material name="LightLilac"/>
    </visual>
    <collision>
      <origin rpy="0 0 0" xyz="0 0 0"/>
      <geometry>
        <!-- TODO: Simpler collision shape -->
        <mesh filename="package://doppel_description/meshes/base.dae" scale="1 1 1"/>
      </geometry>
    </collision>
  </link>
  <gazebo reference="base_link">
    <mu1 value="0"/>
    <mu2 value="0"/>
    <kp value="1e8"/>
    <kd value="1.0"/>
    <fdir1 value="1 0 0"/>
    <minDepth>0.005</minDepth>
    <material>Gazebo/LightLilac</material>
    <turnGravityOff>false</turnGravityOff>
  </gazebo>
  <joint name="joint1" type="revolute">
    <parent link="base_link"/>
    <child link="link1"/>
    <origin rpy="0 0 3.14159265359" xyz="0 0 0.062"/>
    <axis xyz="0 0 1"/>
    <limit effort="44.7" lower="-3.14159265359" upper="3.14159265359" velocity="3.14159265359"/>
    <dynamics damping="1.0" friction="0.0"/>
  </joint>
  <transmission name="joint1_trans">
    <type>transmission_interface/SimpleTransmission</type>
    <joint name="joint1">
      <hardwareInterface>hardware_interface/PositionJointInterface</hardwareInterface>
    </joint>
    <actuator name="joint1_motor">
      <hardwareInterface>hardware_interface/PositionJointInterface</hardwareInterface>
      <mechanicalReduction>1</mechanicalReduction>
    </actuator>
  </transmission>
  <link name="link1">
    <inertial>
      <mass value="2.13134162"/>
      <origin xyz="0 0 0"/>
      <inertia ixx="0.01012037" ixy="0.00034081" ixz="0.00331148" iyy="0.01055121" iyz="0.00071657" izz="0.00237852"/>
    </inertial>
    <visual>
      <origin rpy="0 0 0" xyz="0 0 0"/>
      <geometry>
        <mesh filename="package://doppel_description/meshes/link1.dae" scale="1 1 1"/>
      </geometry>
      <material name="LightLilac"/>
    </visual>
    <collision>
      <origin rpy="0 0 0" xyz="0 0 0"/>
      <geometry>
        <!-- TODO: Simpler collision shape -->
        <mesh filename="package://doppel_description/meshes/link1.dae" scale="1 1 1"/>
      </geometry>
    </collision>
  </link>
  <gazebo reference="link1">
    <mu1 value="0"/>
    <mu2 value="0"/>
    <kp value="1e8"/>
    <kd value="1.0"/>
    <fdir1 value="1 0 0"/>
    <minDepth>0.005</minDepth>
    <material>Gazebo/LightLilac</material>
    <turnGravityOff>false</turnGravityOff>
  </gazebo>
  <joint name="joint2" type="revolute">
    <parent link="link1"/>
    <child link="link2"/>
    <origin rpy="-1.57079632679 0 3.14159265359" xyz="0.054 0 0.063"/>
    <axis xyz="0 0 1"/>
    <limit effort="44.7" lower="-3.14159265359" upper="0" velocity="3.14159265359"/>
    <dynamics damping="1.0" friction="0.0"/>
  </joint>
  <transmission name="joint2_trans">
    <type>transmission_interface/SimpleTransmission</type>
    <joint name="joint2">
      <hardwareInterface>hardware_interface/PositionJointInterface</hardwareInterface>
    </joint>
    <actuator name="joint2_motor">
      <hardwareInterface>hardware_interface/PositionJointInterface</hardwareInterface>
      <mechanicalReduction>1</mechanicalReduction>
    </actuator>
  </transmission>
  <link name="link2">
    <inertial>
      <mass value="1.14165583"/>
      <origin xyz="0.25 0 0"/>
      <inertia ixx="0.0045786" ixy="0.00179706" ixz="-2.524e-05" iyy="0.07792435" iyz="-1.69e-06" izz="0.07451121"/>
    </inertial>
    <visual>
      <origin rpy="0 0 0" xyz="0 0 0"/>
      <geometry>
        <mesh filename="package://doppel_description/meshes/link2.dae" scale="1 1 1"/>
      </geometry>
      <material name="LightishRed"/>
    </visual>
    <collision>
      <origin rpy="0 0 0" xyz="0 0 0"/>
      <geometry>
        <!-- TODO: Simpler collision shape -->
        <mesh filename="package://doppel_description/meshes/link2.dae" scale="1 1 1"/>
      </geometry>
    </collision>
  </link>
  <gazebo reference="link2">
    <mu1 value="0"/>
    <mu2 value="0"/>
    <kp value="1e8"/>
    <kd value="1.0"/>
    <fdir1 value="1 0 0"/>
    <minDepth>0.005</minDepth>
    <material>Gazebo/LightishRed</material>
    <turnGravityOff>false</turnGravityOff>
  </gazebo>
  <joint name="joint3" type="revolute">
    <parent link="link2"/>
    <child link="link3"/>
    <origin rpy="3.14159265359 0 0" xyz="0.435 0 0"/>
    <axis xyz="0 0 1"/>
    <limit effort="44.7" lower="-1.57079632679" upper="2.86" velocity="3.14159265359"/>
    <dynamics damping="1.0" friction="0.0"/>
  </joint>
  <transmission name="joint3_trans">
    <type>transmission_interface/SimpleTransmission</type>
    <joint name="joint3">
      <hardwareInterface>hardware_interface/PositionJointInterface</hardwareInterface>
    </joint>
    <actuator name="joint3_motor">
      <hardwareInterface>hardware_interface/PositionJointInterface</hardwareInterface>
      <mechanicalReduction>1</mechanicalReduction>
    </actuator>
  </transmission>
  <link name="link3">
    <inertial>
      <mass value="2.79024721"/>
      <origin xyz="0.25 0 0"/>
      <inertia ixx="0.00124106" ixy="0.0" ixz="0.00196671" iyy="0.16340234" iyz="0.0" izz="0.16349435"/>
    </inertial>
    <visual>
      <origin rpy="3.14159265359 0 0" xyz="0 0 0"/>
      <geometry>
        <mesh filename="package://doppel_description/meshes/link3.dae" scale="1 1 1"/>
      </geometry>
      <material name="Leaf"/>
    </visual>
    <collision>
      <origin rpy="3.14159265359 0 0" xyz="0 0 0"/>
      <geometry>
        <!-- TODO: Simpler collision shape -->
        <mesh filename="package://doppel_description/meshes/link3.dae" scale="1 1 1"/>
      </geometry>
    </collision>
  </link>
  <gazebo reference="link3">
    <mu1 value="0"/>
    <mu2 value="0"/>
    <kp value="1e8"/>
    <kd value="1.0"/>
    <fdir1 value="1 0 0"/>
    <minDepth>0.005</minDepth>
    <material>Gazebo/Leaf</material>
    <turnGravityOff>false</turnGravityOff>
  </gazebo>
  <joint name="joint4" type="revolute">
    <parent link="link3"/>
    <child link="link4"/>
    <origin rpy="3.14159265359 0 0" xyz="0.450 0 0"/>
    <axis xyz="0 0 1"/>
    <limit effort="44.7" lower="-2.33" upper="2.86" velocity="3.14159265359"/>
    <dynamics damping="1.0" friction="0.0"/>
  </joint>
  <transmission name="joint4_trans">
    <type>transmission_interface/SimpleTransmission</type>
    <joint name="joint4">
      <hardwareInterface>hardware_interface/PositionJointInterface</hardwareInterface>
    </joint>
    <actuator name="joint4_motor">
      <hardwareInterface>hardware_interface/PositionJointInterface</hardwareInterface>
      <mechanicalReduction>1</mechanicalReduction>
    </actuator>
  </transmission>
  <link name="link4">
    <inertial>
      <mass value="2.18514241"/>
      <origin xyz="0.15 0 0"/>
      <inertia ixx="0.00816433" ixy="-0.01841775" ixz="2.52e-06" iyy="0.10879096" iyz="0.0" izz="0.11044867"/>
    </inertial>
    <visual>
      <origin rpy="0 0 0" xyz="0 0 0"/>
      <geometry>
        <mesh filename="package://doppel_description/meshes/link4.dae" scale="1 1 1"/>
      </geometry>
      <material name="DeepSkyBlue"/>
    </visual>
    <collision>
      <origin rpy="0 0 0" xyz="0 0 0"/>
      <geometry>
        <!-- TODO: Simpler collision shape -->
        <mesh filename="package://doppel_description/meshes/link4.dae" scale="1 1 1"/>
      </geometry>
    </collision>
  </link>
  <gazebo reference="link4">
    <mu1 value="0"/>
    <mu2 value="0"/>
    <kp value="1e8"/>
    <kd value="1.0"/>
    <fdir1 value="1 0 0"/>
    <minDepth>0.005</minDepth>
    <material>Gazebo/DeepSkyBlue</material>
    <turnGravityOff>false</turnGravityOff>
  </gazebo>
  <joint name="velodyne_base_mount_joint" type="fixed">
    <origin rpy="1.57079632679 0 0" xyz="0.23 -0.03 0"/>
    <parent link="link4"/>
    <child link="velodyne_base_link"/>
  </joint>
  <link name="velodyne_base_link">
    <inertial>
      <mass value="0.83"/>
      <origin xyz="0 0 0.03585"/>
      <inertia ixx="0.000908059425" ixy="0" ixz="0" iyy="0.000908059425" iyz="0" izz="0.0011049624"/>
    </inertial>
    <visual>
      <geometry>
        <mesh filename="package://velodyne_description/meshes/VLP16_base_1.dae"/>
      </geometry>
    </visual>
    <visual>
      <geometry>
        <mesh filename="package://velodyne_description/meshes/VLP16_base_2.dae"/>
      </geometry>
    </visual>
    <collision>
      <origin rpy="0 0 0" xyz="0 0 0.03585"/>
      <geometry>
        <cylinder length="0.0717" radius="0.0516"/>
      </geometry>
    </collision>
  </link>
  <joint name="velodyne_base_scan_joint" type="fixed">
    <origin rpy="0 0 0" xyz="0 0 0.0377"/>
    <parent link="velodyne_base_link"/>
    <child link="velodyne"/>
  </joint>
  <link name="velodyne">
    <inertial>
      <mass value="0.01"/>
      <origin xyz="0 0 0"/>
      <inertia ixx="1e-7" ixy="0" ixz="0" iyy="1e-7" iyz="0" izz="1e-7"/>
    </inertial>
    <visual>
      <origin xyz="0 0 -0.0377"/>
      <geometry>
        <mesh filename="package://velodyne_description/meshes/VLP16_scan.dae"/>
      </geometry>
    </visual>
  </link>
  <!-- Gazebo requires the velodyne_gazebo_plugins package -->
  <gazebo reference="velodyne">
    <sensor name="velodyne-VLP16" type="ray">
      <pose>0 0 0 0 0 0</pose>
      <visualize>false</visualize>
      <update_rate>10</update_rate>
      <ray>
        <scan>
          <horizontal>
            <samples>440</samples>
            <resolution>1</resolution>
            <min_angle>-3.14159265359</min_angle>
            <max_angle>3.14159265359</max_angle>
          </horizontal>
          <vertical>
            <samples>16</samples>
            <resolution>1</resolution>
            <min_angle>-0.261799387799</min_angle>
            <max_angle> 0.261799387799</max_angle>
          </vertical>
        </scan>
        <range>
          <min>0.3</min>
          <max>131.0</max>
          <resolution>0.001</resolution>
        </range>
        <noise>
          <type>gaussian</type>
          <mean>0.0</mean>
          <stddev>0.0</stddev>
        </noise>
      </ray>
      <plugin filename="libgazebo_ros_velodyne_laser.so" name="gazebo_ros_laser_controller">
        <topicName>velodyne_points</topicName>
        <frameName>velodyne</frameName>
        <min_range>0.9</min_range>
        <max_range>130.0</max_range>
        <gaussianNoise>0.008</gaussianNoise>
      </plugin>
    </sensor>
  </gazebo>
  <joint name="joint5" type="revolute">
    <parent link="link4"/>
    <child link="link5"/>
    <origin rpy="-1.57079632679 0 0" xyz="0.340 -0.004 0"/>
    <axis xyz="0 0 1"/>
    <limit effort="10.9" lower="-1.57079632679" upper="1.57079632679" velocity="3.14159265359"/>
    <dynamics damping="1.0" friction="0.0"/>
  </joint>
  <transmission name="joint5_trans">
    <type>transmission_interface/SimpleTransmission</type>
    <joint name="joint5">
      <hardwareInterface>hardware_interface/PositionJointInterface</hardwareInterface>
    </joint>
    <actuator name="joint5_motor">
      <hardwareInterface>hardware_interface/PositionJointInterface</hardwareInterface>
      <mechanicalReduction>1</mechanicalReduction>
    </actuator>
  </transmission>
  <link name="link5">
    <inertial>
      <mass value="0.03886738"/>
      <origin xyz="0 0 0"/>
      <inertia ixx="2.242e-05" ixy="0.0" ixz="0.0" iyy="7.053e-05" iyz="0.0" izz="7.053e-05"/>
    </inertial>
    <visual>
      <origin rpy="0 0 0" xyz="0 0 0"/>
      <geometry>
        <mesh filename="package://doppel_description/meshes/link5.dae" scale="1 1 1"/>
      </geometry>
      <material name="Pale"/>
    </visual>
    <collision>
      <origin rpy="0 0 0" xyz="0 0 0"/>
      <geometry>
        <!-- TODO: Simpler collision shape -->
        <mesh filename="package://doppel_description/meshes/link5.dae" scale="1 1 1"/>
      </geometry>
    </collision>
  </link>
  <gazebo reference="link5">
    <mu1 value="0"/>
    <mu2 value="0"/>
    <kp value="1e8"/>
    <kd value="1.0"/>
    <fdir1 value="1 0 0"/>
    <minDepth>0.005</minDepth>
    <material>Gazebo/Pale</material>
    <turnGravityOff>false</turnGravityOff>
  </gazebo>
  <joint name="joint6" type="revolute">
    <parent link="link5"/>
    <child link="link6"/>
    <origin rpy="1.57079632679 0 0" xyz="0.072 0 0"/>
    <axis xyz="0 0 1"/>
    <limit effort="10.9" lower="-1.57079632679" upper="1.57079632679" velocity="3.14159265359"/>
    <dynamics damping="1.0" friction="0.0"/>
  </joint>
  <transmission name="joint6_trans">
    <type>transmission_interface/SimpleTransmission</type>
    <joint name="joint6">
      <hardwareInterface>hardware_interface/PositionJointInterface</hardwareInterface>
    </joint>
    <actuator name="joint6_motor">
      <hardwareInterface>hardware_interface/PositionJointInterface</hardwareInterface>
      <mechanicalReduction>1</mechanicalReduction>
    </actuator>
  </transmission>
  <link name="link6">
    <inertial>
      <mass value="0.33654122"/>
      <origin xyz="0.05 0 0"/>
      <inertia ixx="3.04e-05" ixy="0.0" ixz="0.00012974" iyy="0.00085174" iyz="0.0" izz="0.00083169"/>
    </inertial>
    <visual>
      <origin rpy="0 0 0" xyz="0 0 0"/>
      <geometry>
        <mesh filename="package://doppel_description/meshes/link6.dae" scale="1 1 1"/>
      </geometry>
      <material name="Lavender"/>
    </visual>
    <collision>
      <origin rpy="0 0 0" xyz="0 0 0"/>
      <geometry>
        <!-- TODO: Simpler collision shape -->
        <mesh filename="package://doppel_description/meshes/link6.dae" scale="1 1 1"/>
      </geometry>
    </collision>
  </link>
  <gazebo reference="link6">
    <mu1 value="0"/>
    <mu2 value="0"/>
    <kp value="1e8"/>
    <kd value="1.0"/>
    <fdir1 value="1 0 0"/>
    <minDepth>0.005</minDepth>
    <material>Gazebo/Lavender</material>
    <turnGravityOff>false</turnGravityOff>
  </gazebo>
  <joint name="joint7" type="revolute">
    <parent link="link6"/>
    <child link="link7"/>
    <origin rpy="0 1.57079632679 0" xyz="0.109 0 0"/>
    <axis xyz="0 0 1"/>
    <limit effort="10.9" lower="-3.14159265359" upper="3.14159265359" velocity="3.14159265359"/>
    <dynamics damping="1.0" friction="0.0"/>
  </joint>
  <transmission name="joint7_trans">
    <type>transmission_interface/SimpleTransmission</type>
    <joint name="joint7">
      <hardwareInterface>hardware_interface/PositionJointInterface</hardwareInterface>
    </joint>
    <actuator name="joint7_motor">
      <hardwareInterface>hardware_interface/PositionJointInterface</hardwareInterface>
      <mechanicalReduction>1</mechanicalReduction>
    </actuator>
  </transmission>
  <link name="link7">
    <inertial>
      <mass value="0.81594918"/>
      <origin xyz="0 0 0.05"/>
      <inertia ixx="0.00521117" ixy="0.0" ixz="-0.00019767" iyy="0.0070155" iyz="3.23e-06" izz="0.00208949"/>
    </inertial>
    <visual>
      <origin rpy="0 0 0" xyz="0 0 0"/>
      <geometry>
        <mesh filename="package://doppel_description/meshes/link7.dae" scale="1 1 1"/>
      </geometry>
      <material name="LightOrange"/>
    </visual>
    <collision>
      <origin rpy="0 0 0" xyz="0 0 0"/>
      <geometry>
        <!-- TODO: Simpler collision shape -->
        <mesh filename="package://doppel_description/meshes/link7.dae" scale="1 1 1"/>
      </geometry>
    </collision>
  </link>
  <gazebo reference="link7">
    <mu1 value="0"/>
    <mu2 value="0"/>
    <kp value="1e8"/>
    <kd value="1.0"/>
    <fdir1 value="1 0 0"/>
    <minDepth>0.005</minDepth>
    <material>Gazebo/LightOrange</material>
    <turnGravityOff>false</turnGravityOff>
  </gazebo>
  <joint name="grab_dummy" type="revolute">
    <parent link="link7"/>
    <child link="dummy"/>
    <origin rpy="0 0 0" xyz="0.06 0.03 0.05"/>
    <axis xyz="0 0 1"/>
    <limit effort="10.9" lower="-1.57079632679" upper="1.57079632679" velocity="3.14159265359"/>
    <dynamics damping="1.0" friction="0.0"/>
  </joint>
  <transmission name="grab_dummy_trans">
    <type>transmission_interface/SimpleTransmission</type>
    <joint name="grab_dummy">
      <hardwareInterface>hardware_interface/PositionJointInterface</hardwareInterface>
    </joint>
    <actuator name="grab_dummy_motor">
      <hardwareInterface>hardware_interface/PositionJointInterface</hardwareInterface>
      <mechanicalReduction>1</mechanicalReduction>
    </actuator>
  </transmission>
  <link name="dummy">
    <inertial>
      <mass value="0.001"/>
      <origin rpy="0 0 0" xyz="0 0 0"/>
      <inertia ixx="0" ixy="0" ixz="0" iyy="0" iyz="0" izz="0"/>
    </inertial>
    <visual>
      <origin rpy="0 0 0" xyz="0 0 0"/>
      <geometry>
        <box size="0.05 0.01 0.01"/>
      </geometry>
      <material name="Black"/>
    </visual>
    <collision>
      <origin rpy="0 0 0" xyz="0 0 0"/>
      <geometry>
        <box size="0.05 0.01 0.01"/>
      </geometry>
    </collision>
  </link>
  <gazebo reference="dummy">
    <mu1 value="0"/>
    <mu2 value="0"/>
    <kp value="1e8"/>
    <kd value="1.0"/>
    <fdir1 value="1 0 0"/>
    <minDepth>0.005</minDepth>
    <material>Gazebo/Black</material>
    <turnGravityOff>false</turnGravityOff>
  </gazebo>
  <joint name="to_hand_camera" type="fixed">
    <parent link="link7"/>
    <child link="hand_camera"/>
    <origin rpy="1.57079632679 -1.57079632679 0" xyz="0 0 0.12"/>
  </joint>
  <link name="hand_camera">
    <inertial>
      <mass value="0.001"/>
      <origin rpy="0 0 0" xyz="0 0 0"/>
      <inertia ixx="0" ixy="0" ixz="0" iyy="0" iyz="0" izz="0"/>
    </inertial>
    <visual>
      <origin rpy="0 0 0" xyz="0 0 0"/>
      <geometry>
        <box size="0.01 0.02 0.02"/>
      </geometry>
      <material name="Black"/>
    </visual>
    <collision>
      <origin rpy="0 0 0" xyz="0 0 0"/>
      <geometry>
        <box size="0.01 0.02 0.02"/>
      </geometry>
    </collision>
  </link>
  <gazebo reference="hand_camera">
    <mu1 value="0"/>
    <mu2 value="0"/>
    <kp value="1e8"/>
    <kd value="1.0"/>
    <fdir1 value="1 0 0"/>
    <minDepth>0.005</minDepth>
    <material>Gazebo/Black</material>
    <turnGravityOff>false</turnGravityOff>
  </gazebo>
  <!-- camera -->
  <gazebo reference="hand_camera">
    <sensor name="hand_camera" type="camera">
      <update_rate>30.0</update_rate>
      <camera name="hand_camera">
        <horizontal_fov>1.3962634</horizontal_fov>
        <image>
          <width>800</width>
          <height>800</height>
          <format>R8G8B8</format>
        </image>
        <clip>
          <near>0.02</near>
          <far>300</far>
        </clip>
        <noise>
          <type>gaussian</type>
          <!-- Noise is sampled independently per pixel on each frame.
                That pixel's noise value is added to each of its color
                channels, which at that point lie in the range [0,1]. -->
          <mean>0.0</mean>
          <stddev>0.007</stddev>
        </noise>
      </camera>
      <plugin filename="libgazebo_ros_camera.so" name="camera_controller">
        <alwaysOn>true</alwaysOn>
        <updateRate>5.0</updateRate>
        <cameraName>hand_camera</cameraName>
        <imageTopicName>image_raw</imageTopicName>
        <cameraInfoTopicName>camera_info</cameraInfoTopicName>
        <frameName>hand_camera</frameName>
        <hackBaseline>0.07</hackBaseline>
        <distortionK1>0.0</distortionK1>
        <distortionK2>0.0</distortionK2>
        <distortionK3>0.0</distortionK3>
        <distortionT1>0.0</distortionT1>
        <distortionT2>0.0</distortionT2>
      </plugin>
    </sensor>
  </gazebo>
</robot>

